<?xml version="1.0" encoding="utf-8"?>
<!-- This URDF was automatically created by SolidWorks to URDF Exporter! Originally created by Stephen Brawner (brawner@gmail.com)
     Commit Version: 1.6.0-4-g7f85cfe  Build Version: 1.6.7995.38578
     For more information, please see http://wiki.ros.org/sw_urdf_exporter -->
<robot
  name="MR24-DT-A00.00 - URDF">
  <link
    name="base_link">
    <inertial>
      <origin
        xyz="-0.00088592 -0.028119 0.09758"
        rpy="0 0 0" />
      <mass
        value="9.3835" />
      <inertia
        ixx="0.01309"
        ixy="1.8428E-06"
        ixz="-1.0125E-09"
        iyy="0.020768"
        iyz="0.001108"
        izz="0.029266" />
    </inertial>
    <visual>
      <origin
        xyz="0 0 0"
        rpy="0 0 0" />
      <geometry>
        <mesh
          filename="package://MR24-DT-A00.00 - URDF/meshes/base_link.STL" />
      </geometry>
      <material
        name="">
        <color
          rgba="0.75294 0.75294 0.75294 1" />
      </material>
    </visual>
    <collision>
      <origin
        xyz="0 0 0"
        rpy="0 0 0" />
      <geometry>
        <mesh
          filename="package://MR24-DT-A00.00 - URDF/meshes/base_link.STL" />
      </geometry>
    </collision>
  </link>
  <link
    name="Front_Left Wheel">
    <inertial>
      <origin
        xyz="-1.0355E-06 0.0028234 5.9786E-07"
        rpy="0 0 0" />
      <mass
        value="1.4538" />
      <inertia
        ixx="0.0051569"
        ixy="-4.55E-09"
        ixz="-5.2852E-09"
        iyy="0.0075013"
        iyz="2.6248E-09"
        izz="0.0051569" />
    </inertial>
    <visual>
      <origin
        xyz="0 0 0"
        rpy="0 0 0" />
      <geometry>
        <mesh
          filename="package://MR24-DT-A00.00 - URDF/meshes/Front_Left Wheel.STL" />
      </geometry>
      <material
        name="">
        <color
          rgba="0.75294 0.75294 0.75294 1" />
      </material>
    </visual>
    <collision>
      <origin
        xyz="0 0 0"
        rpy="0 0 0" />
      <geometry>
        <mesh
          filename="package://MR24-DT-A00.00 - URDF/meshes/Front_Left Wheel.STL" />
      </geometry>
    </collision>
  </link>
  <joint
    name="Front_Left Wheel Joint"
    type="continuous">
    <origin
      xyz="-0.43855 0.40398 0.0080468"
      rpy="3.1416 -0.74573 -1.5708" />
    <parent
      link="base_link" />
    <child
      link="Front_Left Wheel" />
    <axis
      xyz="0 -1 0" />
  </joint>
  <link
    name="Front_right Wheel">
    <inertial>
      <origin
        xyz="-1.0355E-06 0.0028234 5.9786E-07"
        rpy="0 0 0" />
      <mass
        value="1.4538" />
      <inertia
        ixx="0.0051569"
        ixy="-4.55E-09"
        ixz="-5.2852E-09"
        iyy="0.0075013"
        iyz="2.6248E-09"
        izz="0.0051569" />
    </inertial>
    <visual>
      <origin
        xyz="0 0 0"
        rpy="0 0 0" />
      <geometry>
        <mesh
          filename="package://MR24-DT-A00.00 - URDF/meshes/Front_right Wheel.STL" />
      </geometry>
      <material
        name="">
        <color
          rgba="0.75294 0.75294 0.75294 1" />
      </material>
    </visual>
    <collision>
      <origin
        xyz="0 0 0"
        rpy="0 0 0" />
      <geometry>
        <mesh
          filename="package://MR24-DT-A00.00 - URDF/meshes/Front_right Wheel.STL" />
      </geometry>
    </collision>
  </link>
  <joint
    name="Front_Right Wheel Joint"
    type="continuous">
    <origin
      xyz="0.43855 0.40398 0.0080468"
      rpy="0 -0.043518 -1.5708" />
    <parent
      link="base_link" />
    <child
      link="Front_right Wheel" />
    <axis
      xyz="0 -1 0" />
  </joint>
  <link
    name="Center_Left Wheel">
    <inertial>
      <origin
        xyz="-1.0355E-06 0.0028234 5.9786E-07"
        rpy="0 0 0" />
      <mass
        value="1.4538" />
      <inertia
        ixx="0.0051569"
        ixy="-4.55E-09"
        ixz="-5.2852E-09"
        iyy="0.0075013"
        iyz="2.6248E-09"
        izz="0.0051569" />
    </inertial>
    <visual>
      <origin
        xyz="0 0 0"
        rpy="0 0 0" />
      <geometry>
        <mesh
          filename="package://MR24-DT-A00.00 - URDF/meshes/Center_Left Wheel.STL" />
      </geometry>
      <material
        name="">
        <color
          rgba="0.75294 0.75294 0.75294 1" />
      </material>
    </visual>
    <collision>
      <origin
        xyz="0 0 0"
        rpy="0 0 0" />
      <geometry>
        <mesh
          filename="package://MR24-DT-A00.00 - URDF/meshes/Center_Left Wheel.STL" />
      </geometry>
    </collision>
  </link>
  <joint
    name="Center_Left Wheel Joint"
    type="continuous">
    <origin
      xyz="-0.48455 0 0"
      rpy="-3.1416 0.16137 -1.5708" />
    <parent
      link="base_link" />
    <child
      link="Center_Left Wheel" />
    <axis
      xyz="0 -1 0" />
  </joint>
  <link
    name="Center_Right Wheel">
    <inertial>
      <origin
        xyz="-1.0355E-06 0.0028234 5.9786E-07"
        rpy="0 0 0" />
      <mass
        value="1.4538" />
      <inertia
        ixx="0.0051569"
        ixy="-4.55E-09"
        ixz="-5.2852E-09"
        iyy="0.0075013"
        iyz="2.6248E-09"
        izz="0.0051569" />
    </inertial>
    <visual>
      <origin
        xyz="0 0 0"
        rpy="0 0 0" />
      <geometry>
        <mesh
          filename="package://MR24-DT-A00.00 - URDF/meshes/Center_Right Wheel.STL" />
      </geometry>
      <material
        name="">
        <color
          rgba="0.75294 0.75294 0.75294 1" />
      </material>
    </visual>
    <collision>
      <origin
        xyz="0 0 0"
        rpy="0 0 0" />
      <geometry>
        <mesh
          filename="package://MR24-DT-A00.00 - URDF/meshes/Center_Right Wheel.STL" />
      </geometry>
    </collision>
  </link>
  <joint
    name="Center_Right Wheel Joint"
    type="continuous">
    <origin
      xyz="0.48455 0 0"
      rpy="3.1416 0.15745 1.5708" />
    <parent
      link="base_link" />
    <child
      link="Center_Right Wheel" />
    <axis
      xyz="0 -1 0" />
  </joint>
  <link
    name="Rear_Left Wheel">
    <inertial>
      <origin
        xyz="-1.0355E-06 0.0028234 5.9786E-07"
        rpy="0 0 0" />
      <mass
        value="1.4538" />
      <inertia
        ixx="0.0051569"
        ixy="-4.55E-09"
        ixz="-5.2852E-09"
        iyy="0.0075013"
        iyz="2.6248E-09"
        izz="0.0051569" />
    </inertial>
    <visual>
      <origin
        xyz="0 0 0"
        rpy="0 0 0" />
      <geometry>
        <mesh
          filename="package://MR24-DT-A00.00 - URDF/meshes/Rear_Left Wheel.STL" />
      </geometry>
      <material
        name="">
        <color
          rgba="0.75294 0.75294 0.75294 1" />
      </material>
    </visual>
    <collision>
      <origin
        xyz="0 0 0"
        rpy="0 0 0" />
      <geometry>
        <mesh
          filename="package://MR24-DT-A00.00 - URDF/meshes/Rear_Left Wheel.STL" />
      </geometry>
    </collision>
  </link>
  <joint
    name="Rear_Left Wheel Joint"
    type="continuous">
    <origin
      xyz="-0.48455 -0.39807 0.016315"
      rpy="-3.1416 -1.4933 -1.5708" />
    <parent
      link="base_link" />
    <child
      link="Rear_Left Wheel" />
    <axis
      xyz="0 -1 0" />
  </joint>
  <link
    name="Rear_Right Wheel">
    <inertial>
      <origin
        xyz="-1.0355E-06 0.0028234 5.9786E-07"
        rpy="0 0 0" />
      <mass
        value="1.4538" />
      <inertia
        ixx="0.0051569"
        ixy="-4.55E-09"
        ixz="-5.2852E-09"
        iyy="0.0075013"
        iyz="2.6248E-09"
        izz="0.0051569" />
    </inertial>
    <visual>
      <origin
        xyz="0 0 0"
        rpy="0 0 0" />
      <geometry>
        <mesh
          filename="package://MR24-DT-A00.00 - URDF/meshes/Rear_Right Wheel.STL" />
      </geometry>
      <material
        name="">
        <color
          rgba="0.75294 0.75294 0.75294 1" />
      </material>
    </visual>
    <collision>
      <origin
        xyz="0 0 0"
        rpy="0 0 0" />
      <geometry>
        <mesh
          filename="package://MR24-DT-A00.00 - URDF/meshes/Rear_Right Wheel.STL" />
      </geometry>
    </collision>
  </link>
  <joint
    name="Rear_Right Wheel Joint"
    type="continuous">
    <origin
      xyz="0.48455 -0.39807 0.016315"
      rpy="3.1416 0.15881 1.5708" />
    <parent
      link="base_link" />
    <child
      link="Rear_Right Wheel" />
    <axis
      xyz="0 -1 0" />
  </joint>
</robot>
